Watching for file changes with StatReloader
X:\Projects\Работа\IsFaceCV\face\face\settings.py changed, reloading.
2022-04-28 18:01:36.341465;[INFO];visitor on main template
2022-04-28 18:02:20.713597;[INFO];visitor on main template
2022-04-28 18:03:54.150837;[INFO];SITE|   VISITOR  
2022-04-28 18:07:04.405088;[INFO];visitor on main template
2022-04-28 18:07:15.217280;[INFO];visitor on main template
2022-04-28 18:07:16.257186;[INFO];visitor on main template
2022-04-28 18:07:17.047410;[INFO];visitor on main template
2022-04-28 18:07:17.813008;[INFO];visitor on main template
2022-04-28 18:07:18.886894;[INFO];visitor on main template
2022-04-28 18:12:22.890099;[INFO];visitor on main template
2022-04-28 18:12:50.532924;[ERROR];exception in getting db data
2022-04-28 18:12:58.232258;[INFO];SITE|   VISITOR  
2022-04-28 18:13:14.978963;[INFO];SITE|   VISITOR  
Internal Server Error: /backendofreact
Traceback (most recent call last):
  File "C:\Users\Admin\AppData\Roaming\Python\Python310\site-packages\django\db\backends\base\base.py", line 244, in ensure_connection
    self.connect()
  File "C:\Users\Admin\AppData\Roaming\Python\Python310\site-packages\django\utils\asyncio.py", line 26, in inner
    return func(*args, **kwargs)
  File "C:\Users\Admin\AppData\Roaming\Python\Python310\site-packages\django\db\backends\base\base.py", line 225, in connect
    self.connection = self.get_new_connection(conn_params)
  File "C:\Users\Admin\AppData\Roaming\Python\Python310\site-packages\django\utils\asyncio.py", line 26, in inner
    return func(*args, **kwargs)
  File "C:\Users\Admin\AppData\Roaming\Python\Python310\site-packages\django\db\backends\postgresql\base.py", line 203, in get_new_connection
    connection = Database.connect(**conn_params)
  File "C:\Python310\lib\site-packages\psycopg2\__init__.py", line 122, in connect
    conn = _connect(dsn, connection_factory=connection_factory, **kwasync)
psycopg2.OperationalError: connection to server at "192.168.35.197", port 5432 failed: Connection timed out (0x0000274C/10060)
	Is the server running on that host and accepting TCP/IP connections?


The above exception was the direct cause of the following exception:

Traceback (most recent call last):
  File "X:\Projects\Работа\IsFaceCV\face\upload_app\views.py", line 120, in index
    active, person, name = active_code(face_token_ch)
  File "X:\Projects\Работа\IsFaceCV\face\upload_app\modules\db.py", line 7, in active_code
    person  = Requests.objects.get(invite_code = code)
  File "C:\Users\Admin\AppData\Roaming\Python\Python310\site-packages\django\db\models\manager.py", line 85, in manager_method
    return getattr(self.get_queryset(), name)(*args, **kwargs)
  File "C:\Users\Admin\AppData\Roaming\Python\Python310\site-packages\django\db\models\query.py", line 492, in get
    num = len(clone)
  File "C:\Users\Admin\AppData\Roaming\Python\Python310\site-packages\django\db\models\query.py", line 302, in __len__
    self._fetch_all()
  File "C:\Users\Admin\AppData\Roaming\Python\Python310\site-packages\django\db\models\query.py", line 1507, in _fetch_all
    self._result_cache = list(self._iterable_class(self))
  File "C:\Users\Admin\AppData\Roaming\Python\Python310\site-packages\django\db\models\query.py", line 57, in __iter__
    results = compiler.execute_sql(
  File "C:\Users\Admin\AppData\Roaming\Python\Python310\site-packages\django\db\models\sql\compiler.py", line 1359, in execute_sql
    cursor = self.connection.cursor()
  File "C:\Users\Admin\AppData\Roaming\Python\Python310\site-packages\django\utils\asyncio.py", line 26, in inner
    return func(*args, **kwargs)
  File "C:\Users\Admin\AppData\Roaming\Python\Python310\site-packages\django\db\backends\base\base.py", line 284, in cursor
    return self._cursor()
  File "C:\Users\Admin\AppData\Roaming\Python\Python310\site-packages\django\db\backends\base\base.py", line 260, in _cursor
    self.ensure_connection()
  File "C:\Users\Admin\AppData\Roaming\Python\Python310\site-packages\django\utils\asyncio.py", line 26, in inner
    return func(*args, **kwargs)
  File "C:\Users\Admin\AppData\Roaming\Python\Python310\site-packages\django\db\backends\base\base.py", line 243, in ensure_connection
    with self.wrap_database_errors:
  File "C:\Users\Admin\AppData\Roaming\Python\Python310\site-packages\django\db\utils.py", line 91, in __exit__
    raise dj_exc_value.with_traceback(traceback) from exc_value
  File "C:\Users\Admin\AppData\Roaming\Python\Python310\site-packages\django\db\backends\base\base.py", line 244, in ensure_connection
    self.connect()
  File "C:\Users\Admin\AppData\Roaming\Python\Python310\site-packages\django\utils\asyncio.py", line 26, in inner
    return func(*args, **kwargs)
  File "C:\Users\Admin\AppData\Roaming\Python\Python310\site-packages\django\db\backends\base\base.py", line 225, in connect
    self.connection = self.get_new_connection(conn_params)
  File "C:\Users\Admin\AppData\Roaming\Python\Python310\site-packages\django\utils\asyncio.py", line 26, in inner
    return func(*args, **kwargs)
  File "C:\Users\Admin\AppData\Roaming\Python\Python310\site-packages\django\db\backends\postgresql\base.py", line 203, in get_new_connection
    connection = Database.connect(**conn_params)
  File "C:\Python310\lib\site-packages\psycopg2\__init__.py", line 122, in connect
    conn = _connect(dsn, connection_factory=connection_factory, **kwasync)
django.db.utils.OperationalError: connection to server at "192.168.35.197", port 5432 failed: Connection timed out (0x0000274C/10060)
	Is the server running on that host and accepting TCP/IP connections?


During handling of the above exception, another exception occurred:

Traceback (most recent call last):
  File "C:\Users\Admin\AppData\Roaming\Python\Python310\site-packages\django\core\handlers\exception.py", line 55, in inner
    response = get_response(request)
  File "C:\Users\Admin\AppData\Roaming\Python\Python310\site-packages\django\core\handlers\base.py", line 197, in _get_response
    response = wrapped_callback(request, *callback_args, **callback_kwargs)
  File "X:\Projects\Работа\IsFaceCV\face\upload_app\views.py", line 128, in index
    logger.error(str(datetime.datetime.now())+ + ";[ERROR];"+ + "API|   Exception in database ")
TypeError: bad operand type for unary +: 'str'
2022-04-28 18:29:17.084615;[ERROR];exception in getting db data
2022-04-28 18:29:17.122613;[ERROR];exception in getting db data
2022-04-28 18:29:26.541472;[INFO];SITE|   VISITOR  
